<?xml version="1.0" encoding="utf-8"?>
<!-- This URDF was automatically created by SolidWorks to URDF Exporter! Originally created by Stephen Brawner (brawner@gmail.com) 
     Commit Version: 1.6.0-4-g7f85cfe  Build Version: 1.6.7995.38578
     For more information, please see http://wiki.ros.org/sw_urdf_exporter -->
<robot
  name="Bigdog">
  <link
    name="BODY">
    <inertial>
      <origin
        xyz="-6.601E-06 6.0313E-07 -0.0033948"
        rpy="0 0 0" />
      <mass
        value="7.1237" />
      <inertia
        ixx="0.05681"
        ixy="0"
        ixz="-1E-05"
        iyy="0.07575"
        iyz="-1E-05"
        izz="0.10574" />
    </inertial>
    <visual>
      <origin
        xyz="0 0 0"
        rpy="0 0 0" />
      <geometry>
        <mesh
          filename="package://robot-Bigdog-A.SLDASM/meshes/BODY.STL" />
      </geometry>
      <material
        name="">
        <color
          rgba="0.75294 0.75294 0.75294 1" />
      </material>
    </visual>
    <collision>
      <origin
        xyz="0 0 0"
        rpy="0 0 0" />
      <geometry>
        <mesh
          filename="package://robot-Bigdog-A.SLDASM/meshes/BODY.STL" />
      </geometry>
    </collision>
  </link>
  <link
    name="FR_1">
    <inertial>
      <origin
        xyz="0.061252 0.0085205 0.00031161"
        rpy="0 0 0" />
      <mass
        value="0.33434" />
      <inertia
        ixx="0.00024"
        ixy="-1E-05"
        ixz="0"
        iyy="0.00041"
        iyz="0"
        izz="0.00029" />
    </inertial>
    <visual>
      <origin
        xyz="0 0 0"
        rpy="0 0 0" />
      <geometry>
        <mesh
          filename="package://robot-Bigdog-A.SLDASM/meshes/FR_1.STL" />
      </geometry>
      <material
        name="">
        <color
          rgba="0.75294 0.75294 0.75294 1" />
      </material>
    </visual>
    <collision>
      <origin
        xyz="0 0 0"
        rpy="0 0 0" />
      <geometry>
        <mesh
          filename="package://robot-Bigdog-A.SLDASM/meshes/FR_1.STL" />
      </geometry>
    </collision>
  </link>
  <joint
    name="FR_1A"
    type="revolute">
    <origin
      xyz="0.1393 -0.061 0"
      rpy="0 0 0" />
    <parent
      link="BODY" />
    <child
      link="FR_1" />
    <axis
      xyz="1 0 0" />
    <limit
      lower="-3.14"
      upper="3.14"
      effort="100"
      velocity="50" />
  </joint>
  <link
    name="FR_2">
    <inertial>
      <origin
        xyz="-0.033941 -0.061444 -0.031612"
        rpy="0 0 0" />
      <mass
        value="1.1104" />
      <inertia
        ixx="0.00351"
        ixy="-0.00045"
        ixz="-0.00244"
        iyy="0.00607"
        iyz="-0.00042"
        izz="0.00358" />
    </inertial>
    <visual>
      <origin
        xyz="0 0 0"
        rpy="0 0 0" />
      <geometry>
        <mesh
          filename="package://robot-Bigdog-A.SLDASM/meshes/FR_2.STL" />
      </geometry>
      <material
        name="">
        <color
          rgba="0.75294 0.75294 0.75294 1" />
      </material>
    </visual>
    <collision>
      <origin
        xyz="0 0 0"
        rpy="0 0 0" />
      <geometry>
        <mesh
          filename="package://robot-Bigdog-A.SLDASM/meshes/FR_2.STL" />
      </geometry>
    </collision>
  </link>
  <joint
    name="FR_2A"
    type="revolute">
    <origin
      xyz="0.065 -0.0115 0"
      rpy="0 0 0" />
    <parent
      link="FR_1" />
    <child
      link="FR_2" />
    <axis
      xyz="0 1 0" />
    <limit
      lower="-3.14"
      upper="3.14"
      effort="100"
      velocity="50" />
  </joint>
  <link
    name="FR_3">
    <inertial>
      <origin
        xyz="0.052368 -0.016301 -0.063878"
        rpy="0 0 0" />
      <mass
        value="0.10582" />
      <inertia
        ixx="0.00037"
        ixy="0"
        ixz="0.00029"
        iyy="0.00061"
        iyz="0"
        izz="0.00025" />
    </inertial>
    <visual>
      <origin
        xyz="0 0 0"
        rpy="0 0 0" />
      <geometry>
        <mesh
          filename="package://robot-Bigdog-A.SLDASM/meshes/FR_3.STL" />
      </geometry>
      <material
        name="">
        <color
          rgba="0.75294 0.75294 0.75294 1" />
      </material>
    </visual>
    <collision>
      <origin
        xyz="0 0 0"
        rpy="0 0 0" />
      <geometry>
        <mesh
          filename="package://robot-Bigdog-A.SLDASM/meshes/FR_3.STL" />
      </geometry>
    </collision>
  </link>
  <joint
    name="FR_3A"
    type="revolute">
    <origin
      xyz="-0.1247 -0.0572 -0.14861"
      rpy="0 0 0" />
    <parent
      link="FR_2" />
    <child
      link="FR_3" />
    <axis
      xyz="0 1 0" />
    <limit
      lower="-3.14"
      upper="3.14"
      effort="100"
      velocity="50" />
  </joint>
  <link
    name="FR_4">
    <inertial>
      <origin
        xyz="0.0017765 3.0979E-07 -0.011458"
        rpy="0 0 0" />
      <mass
        value="0.034657" />
      <inertia
        ixx="5.6404E-06"
        ixy="1.8541E-09"
        ixz="1.9984E-07"
        iyy="8.2173E-06"
        iyz="2.6192E-10"
        izz="6.9941E-06" />
    </inertial>
    <visual>
      <origin
        xyz="0 0 0"
        rpy="0 0 0" />
      <geometry>
        <mesh
          filename="package://robot-Bigdog-A.SLDASM/meshes/FR_4.STL" />
      </geometry>
      <material
        name="">
        <color
          rgba="1 1 1 1" />
      </material>
    </visual>
    <collision>
      <origin
        xyz="0 0 0"
        rpy="0 0 0" />
      <geometry>
        <mesh
          filename="package://robot-Bigdog-A.SLDASM/meshes/FR_4.STL" />
      </geometry>
    </collision>
  </link>
  <joint
    name="FR_4A"
    type="fixed">
    <origin
      xyz="0.11222 -0.0163 -0.14758"
      rpy="0 0 0" />
    <parent
      link="FR_3" />
    <child
      link="FR_4" />
    <axis
      xyz="0 0 0" />
  </joint>
  <link
    name="FL_1">
    <inertial>
      <origin
        xyz="0.061256 -0.0085206 0.00028119"
        rpy="0 0 0" />
      <mass
        value="0.33435" />
      <inertia
        ixx="0.00024"
        ixy="1E-05"
        ixz="0"
        iyy="0.00041"
        iyz="0"
        izz="0.00029" />
    </inertial>
    <visual>
      <origin
        xyz="0 0 0"
        rpy="0 0 0" />
      <geometry>
        <mesh
          filename="package://robot-Bigdog-A.SLDASM/meshes/FL_1.STL" />
      </geometry>
      <material
        name="">
        <color
          rgba="0.75294 0.75294 0.75294 1" />
      </material>
    </visual>
    <collision>
      <origin
        xyz="0 0 0"
        rpy="0 0 0" />
      <geometry>
        <mesh
          filename="package://robot-Bigdog-A.SLDASM/meshes/FL_1.STL" />
      </geometry>
    </collision>
  </link>
  <joint
    name="FL_1A"
    type="revolute">
    <origin
      xyz="0.1393 0.061 0"
      rpy="0 0 0" />
    <parent
      link="BODY" />
    <child
      link="FL_1" />
    <axis
      xyz="1 0 0" />
    <limit
      lower="-3.14"
      upper="3.14"
      effort="100"
      velocity="50" />
  </joint>
  <link
    name="FL_2">
    <inertial>
      <origin
        xyz="-0.033941 0.061444 -0.031616"
        rpy="0 0 0" />
      <mass
        value="1.1103" />
      <inertia
        ixx="0.00351"
        ixy="0.00045"
        ixz="-0.00244"
        iyy="0.00607"
        iyz="0.00042"
        izz="0.00358" />
    </inertial>
    <visual>
      <origin
        xyz="0 0 0"
        rpy="0 0 0" />
      <geometry>
        <mesh
          filename="package://robot-Bigdog-A.SLDASM/meshes/FL_2.STL" />
      </geometry>
      <material
        name="">
        <color
          rgba="0.75294 0.75294 0.75294 1" />
      </material>
    </visual>
    <collision>
      <origin
        xyz="0 0 0"
        rpy="0 0 0" />
      <geometry>
        <mesh
          filename="package://robot-Bigdog-A.SLDASM/meshes/FL_2.STL" />
      </geometry>
    </collision>
  </link>
  <joint
    name="FL_2A"
    type="revolute">
    <origin
      xyz="0.065 0.0115 0"
      rpy="0 0 0" />
    <parent
      link="FL_1" />
    <child
      link="FL_2" />
    <axis
      xyz="0 1 0" />
    <limit
      lower="-3.14"
      upper="3.14"
      effort="100"
      velocity="50" />
  </joint>
  <link
    name="FL_3">
    <inertial>
      <origin
        xyz="0.052437 0.016299 -0.063821"
        rpy="0 0 0" />
      <mass
        value="0.10582" />
      <inertia
        ixx="0.00037"
        ixy="0"
        ixz="0.00029"
        iyy="0.00061"
        iyz="0"
        izz="0.00025" />
    </inertial>
    <visual>
      <origin
        xyz="0 0 0"
        rpy="0 0 0" />
      <geometry>
        <mesh
          filename="package://robot-Bigdog-A.SLDASM/meshes/FL_3.STL" />
      </geometry>
      <material
        name="">
        <color
          rgba="0.75294 0.75294 0.75294 1" />
      </material>
    </visual>
    <collision>
      <origin
        xyz="0 0 0"
        rpy="0 0 0" />
      <geometry>
        <mesh
          filename="package://robot-Bigdog-A.SLDASM/meshes/FL_3.STL" />
      </geometry>
    </collision>
  </link>
  <joint
    name="FL_3A"
    type="revolute">
    <origin
      xyz="-0.1247 0.0572 -0.14861"
      rpy="0 0 0" />
    <parent
      link="FL_2" />
    <child
      link="FL_3" />
    <axis
      xyz="0 1 0" />
    <limit
      lower="-3.14"
      upper="3.14"
      effort="100"
      velocity="50" />
  </joint>
  <link
    name="FL_4">
    <inertial>
      <origin
        xyz="0.00178891349632576 3.09717608393267E-07 -0.0114556023572297"
        rpy="0 0 0" />
      <mass
        value="0.034656887242965" />
      <inertia
        ixx="5.64084567303261E-06"
        ixy="1.85384550092827E-09"
        ixz="2.01305184628335E-07"
        iyy="8.21732246303812E-06"
        iyz="2.63948675037413E-10"
        izz="6.99364784955886E-06" />
    </inertial>
    <visual>
      <origin
        xyz="0 0 0"
        rpy="0 0 0" />
      <geometry>
        <mesh
          filename="package://robot-Bigdog-A.SLDASM/meshes/FL_4.STL" />
      </geometry>
      <material
        name="">
        <color
          rgba="1 1 1 1" />
      </material>
    </visual>
    <collision>
      <origin
        xyz="0 0 0"
        rpy="0 0 0" />
      <geometry>
        <mesh
          filename="package://robot-Bigdog-A.SLDASM/meshes/FL_4.STL" />
      </geometry>
    </collision>
  </link>
  <joint
    name="FL_4A"
    type="fixed">
    <origin
      xyz="0.11238 0.0163 -0.14746"
      rpy="0 0 0" />
    <parent
      link="FL_3" />
    <child
      link="FL_4" />
    <axis
      xyz="0 0 0" />
  </joint>
  <link
    name="BR_1">
    <inertial>
      <origin
        xyz="-0.061256 0.0085206 0.00028119"
        rpy="0 0 0" />
      <mass
        value="0.33435" />
      <inertia
        ixx="0.00024"
        ixy="1E-05"
        ixz="0"
        iyy="0.00041"
        iyz="0"
        izz="0.00029" />
    </inertial>
    <visual>
      <origin
        xyz="0 0 0"
        rpy="0 0 0" />
      <geometry>
        <mesh
          filename="package://robot-Bigdog-A.SLDASM/meshes/BR_1.STL" />
      </geometry>
      <material
        name="">
        <color
          rgba="0.75294 0.75294 0.75294 1" />
      </material>
    </visual>
    <collision>
      <origin
        xyz="0 0 0"
        rpy="0 0 0" />
      <geometry>
        <mesh
          filename="package://robot-Bigdog-A.SLDASM/meshes/BR_1.STL" />
      </geometry>
    </collision>
  </link>
  <joint
    name="BR_1A"
    type="revolute">
    <origin
      xyz="-0.1393 -0.061 0"
      rpy="0 0 0" />
    <parent
      link="BODY" />
    <child
      link="BR_1" />
    <axis
      xyz="1 0 0" />
    <limit
      lower="-3.14"
      upper="3.14"
      effort="100"
      velocity="50" />
  </joint>
  <link
    name="BR_2">
    <inertial>
      <origin
        xyz="-0.033941 -0.061444 -0.031612"
        rpy="0 0 0" />
      <mass
        value="1.1104" />
      <inertia
        ixx="0.00351"
        ixy="-0.00045"
        ixz="-0.00244"
        iyy="0.00607"
        iyz="-0.00042"
        izz="0.00358" />
    </inertial>
    <visual>
      <origin
        xyz="0 0 0"
        rpy="0 0 0" />
      <geometry>
        <mesh
          filename="package://robot-Bigdog-A.SLDASM/meshes/BR_2.STL" />
      </geometry>
      <material
        name="">
        <color
          rgba="0.75294 0.75294 0.75294 1" />
      </material>
    </visual>
    <collision>
      <origin
        xyz="0 0 0"
        rpy="0 0 0" />
      <geometry>
        <mesh
          filename="package://robot-Bigdog-A.SLDASM/meshes/BR_2.STL" />
      </geometry>
    </collision>
  </link>
  <joint
    name="BR_2A"
    type="revolute">
    <origin
      xyz="-0.065 -0.0115 0"
      rpy="0 0 0" />
    <parent
      link="BR_1" />
    <child
      link="BR_2" />
    <axis
      xyz="0 1 0" />
    <limit
      lower="-3.14"
      upper="3.14"
      effort="100"
      velocity="50" />
  </joint>
  <link
    name="BR_3">
    <inertial>
      <origin
        xyz="0.052359 -0.016301 -0.063885"
        rpy="0 0 0" />
     <mass
        value="0.10582" />
      <inertia
        ixx="0.00037"
        ixy="0"
        ixz="0.00029"
        iyy="0.00061"
        iyz="0"
        izz="0.00025" />
    </inertial>
    <visual>
      <origin
        xyz="0 0 0"
        rpy="0 0 0" />
      <geometry>
        <mesh
          filename="package://robot-Bigdog-A.SLDASM/meshes/BR_3.STL" />
      </geometry>
      <material
        name="">
        <color
          rgba="0.75294 0.75294 0.75294 1" />
      </material>
    </visual>
    <collision>
      <origin
        xyz="0 0 0"
        rpy="0 0 0" />
      <geometry>
        <mesh
          filename="package://robot-Bigdog-A.SLDASM/meshes/BR_3.STL" />
      </geometry>
    </collision>
  </link>
  <joint
    name="BR_3A"
    type="revolute">
    <origin
      xyz="-0.1247 -0.0572 -0.14861"
      rpy="0 0 0" />
    <parent
      link="BR_2" />
    <child
      link="BR_3" />
    <axis
      xyz="0 1 0" />
    <limit
      lower="-3.14"
      upper="3.14"
      effort="100"
      velocity="50" />
  </joint>
  <link
    name="BR_4">
    <inertial>
      <origin
        xyz="0.00177499106550391 3.09798694614338E-07 -0.0114577678053921"
        rpy="0 0 0" />
      <mass
        value="0.0346568887557471" />
      <inertia
        ixx="5.64035838651341E-06"
        ixy="1.85417993437784E-09"
        ixz="1.99660724135235E-07"
        iyy="8.2173226004451E-06"
        iyz="2.61673167246472E-10"
        izz="6.9941354022534E-06" />
    </inertial>
    <visual>
      <origin
        xyz="0 0 0"
        rpy="0 0 0" />
      <geometry>
        <mesh
          filename="package://robot-Bigdog-A.SLDASM/meshes/BR_4.STL" />
      </geometry>
      <material
        name="">
        <color
          rgba="1 1 1 1" />
      </material>
    </visual>
    <collision>
      <origin
        xyz="0 0 0"
        rpy="0 0 0" />
      <geometry>
        <mesh
          filename="package://robot-Bigdog-A.SLDASM/meshes/BR_4.STL" />
      </geometry>
    </collision>
  </link>
  <joint
    name="BR_4A"
    type="fixed">
    <origin
      xyz="0.1122 -0.0163 -0.14759"
      rpy="0 0 0" />
    <parent
      link="BR_3" />
    <child
      link="BR_4" />
    <axis
      xyz="0 0 0" />
  </joint>
  <link
    name="BL_1">
    <inertial>
      <origin
        xyz="-0.061252 -0.0085205 0.00031161"
        rpy="0 0 0" />
      <mass
        value="0.33434" />
      <inertia
        ixx="0.00024"
        ixy="-1E-05"
        ixz="0"
        iyy="0.00041"
        iyz="0"
        izz="0.00029" />
    </inertial>
    <visual>
      <origin
        xyz="0 0 0"
        rpy="0 0 0" />
      <geometry>
        <mesh
          filename="package://robot-Bigdog-A.SLDASM/meshes/BL_1.STL" />
      </geometry>
      <material
        name="">
        <color
          rgba="0.75294 0.75294 0.75294 1" />
      </material>
    </visual>
    <collision>
      <origin
        xyz="0 0 0"
        rpy="0 0 0" />
      <geometry>
        <mesh
          filename="package://robot-Bigdog-A.SLDASM/meshes/BL_1.STL" />
      </geometry>
    </collision>
  </link>
  <joint
    name="BL_1A"
    type="revolute">
    <origin
      xyz="-0.1393 0.061 0"
      rpy="0 0 0" />
    <parent
      link="BODY" />
    <child
      link="BL_1" />
    <axis
      xyz="1 0 0" />
    <limit
      lower="-3.14"
      upper="3.14"
      effort="100"
      velocity="50" />
  </joint>
  <link
    name="BL_2">
    <inertial>
      <origin
        xyz="-0.033941 0.061444 -0.031616"
        rpy="0 0 0" />
      <mass
        value="1.1103" />
      <inertia
        ixx="0.00351"
        ixy="0.00045"
        ixz="-0.00244"
        iyy="0.00607"
        iyz="0.00042"
        izz="0.00358" />
    </inertial>
    <visual>
      <origin
        xyz="0 0 0"
        rpy="0 0 0" />
      <geometry>
        <mesh
          filename="package://robot-Bigdog-A.SLDASM/meshes/BL_2.STL" />
      </geometry>
      <material
        name="">
        <color
          rgba="0.75294 0.75294 0.75294 1" />
      </material>
    </visual>
    <collision>
      <origin
        xyz="0 0 0"
        rpy="0 0 0" />
      <geometry>
        <mesh
          filename="package://robot-Bigdog-A.SLDASM/meshes/BL_2.STL" />
      </geometry>
    </collision>
  </link>
  <joint
    name="BL_2A"
    type="revolute">
    <origin
      xyz="-0.065 0.0115 0"
      rpy="0 0 0" />
    <parent
      link="BL_1" />
    <child
      link="BL_2" />
    <axis
      xyz="0 1 0" />
    <limit
      lower="-3.14"
      upper="3.14"
      effort="100"
      velocity="50" />
  </joint>
  <link
    name="BL_3">
    <inertial>
      <origin
        xyz="0.052358 0.016299 -0.063886"
        rpy="0 0 0" />
     <mass
        value="0.10582" />
      <inertia
        ixx="0.00037"
        ixy="0"
        ixz="0.00029"
        iyy="0.00061"
        iyz="0"
        izz="0.00025" />
    </inertial>
    <visual>
      <origin
        xyz="0 0 0"
        rpy="0 0 0" />
      <geometry>
        <mesh
          filename="package://robot-Bigdog-A.SLDASM/meshes/BL_3.STL" />
      </geometry>
      <material
        name="">
        <color
          rgba="0.75294 0.75294 0.75294 1" />
      </material>
    </visual>
    <collision>
      <origin
        xyz="0 0 0"
        rpy="0 0 0" />
      <geometry>
        <mesh
          filename="package://robot-Bigdog-A.SLDASM/meshes/BL_3.STL" />
      </geometry>
    </collision>
  </link>
  <joint
    name="BL_3A"
    type="revolute">
    <origin
      xyz="-0.1247 0.0572 -0.14861"
      rpy="0 0 0" />
    <parent
      link="BL_2" />
    <child
      link="BL_3" />
    <axis
      xyz="0 1 0" />
    <limit
      lower="-3.14"
      upper="3.14"
      effort="100"
      velocity="50" />
  </joint>
  <link
    name="BL_4">
    <inertial>
      <origin
        xyz="0.00177474407803635 3.09800131159665E-07 -0.0114578060645815"
        rpy="0 0 0" />
      <mass
        value="0.0346568887825792" />
      <inertia
        ixx="5.64034977883528E-06"
        ixy="1.85418584154819E-09"
        ixz="1.99631543104731E-07"
        iyy="8.21732260288241E-06"
        iyz="2.61632799188873E-10"
        izz="6.99414401465298E-06" />
    </inertial>
    <visual>
      <origin
        xyz="0 0 0"
        rpy="0 0 0" />
      <geometry>
        <mesh
          filename="package://robot-Bigdog-A.SLDASM/meshes/BL_4.STL" />
      </geometry>
      <material
        name="">
        <color
          rgba="1 1 1 1" />
      </material>
    </visual>
    <collision>
      <origin
        xyz="0 0 0"
        rpy="0 0 0" />
      <geometry>
        <mesh
          filename="package://robot-Bigdog-A.SLDASM/meshes/BL_4.STL" />
      </geometry>
    </collision>
  </link>
  <joint
    name="BL_4A"
    type="fixed">
    <origin
      xyz="0.1122 0.0163 -0.1476"
      rpy="0 0 0" />
    <parent
      link="BL_3" />
    <child
      link="BL_4" />
    <axis
      xyz="0 0 0" />
  </joint>
</robot>